INFO:aiogram:Bot: Ibn Sino salomatlik markazi [@ibnsino_salomatlik_markazi_bot]
WARNING:aiogram:Updates were skipped successfully.
INFO:aiogram.dispatcher.dispatcher:Start polling.
INFO:aiogram.dispatcher.dispatcher:Stop polling...
WARNING:aiogram:Goodbye!
Bot is online
Member already exists in the database
INFO:aiogram:Bot: Ibn Sino salomatlik markazi [@ibnsino_salomatlik_markazi_bot]
WARNING:aiogram:Updates were skipped successfully.
INFO:aiogram.dispatcher.dispatcher:Start polling.
ERROR:aiogram.dispatcher.dispatcher:Cause exception while getting updates.
Traceback (most recent call last):
  File "/home/ubuntu/.local/lib/python3.10/site-packages/aiogram/dispatcher/dispatcher.py", line 381, in start_polling
    updates = await self.bot.get_updates(
  File "/home/ubuntu/.local/lib/python3.10/site-packages/aiogram/bot/bot.py", line 110, in get_updates
    result = await self.request(api.Methods.GET_UPDATES, payload)
  File "/home/ubuntu/.local/lib/python3.10/site-packages/aiogram/bot/base.py", line 236, in request
    return await api.make_request(await self.get_session(), self.server, self.__token, method, data, files,
  File "/home/ubuntu/.local/lib/python3.10/site-packages/aiogram/bot/api.py", line 140, in make_request
    return check_result(method, response.content_type, response.status, await response.text())
  File "/home/ubuntu/.local/lib/python3.10/site-packages/aiogram/bot/api.py", line 111, in check_result
    raise exceptions.RetryAfter(parameters.retry_after)
aiogram.utils.exceptions.RetryAfter: Flood control exceeded. Retry in 5 seconds.
ERROR:aiogram.dispatcher.dispatcher:Cause exception while getting updates.
Traceback (most recent call last):
  File "/home/ubuntu/.local/lib/python3.10/site-packages/aiogram/dispatcher/dispatcher.py", line 381, in start_polling
    updates = await self.bot.get_updates(
  File "/home/ubuntu/.local/lib/python3.10/site-packages/aiogram/bot/bot.py", line 110, in get_updates
    result = await self.request(api.Methods.GET_UPDATES, payload)
  File "/home/ubuntu/.local/lib/python3.10/site-packages/aiogram/bot/base.py", line 236, in request
    return await api.make_request(await self.get_session(), self.server, self.__token, method, data, files,
  File "/home/ubuntu/.local/lib/python3.10/site-packages/aiogram/bot/api.py", line 140, in make_request
    return check_result(method, response.content_type, response.status, await response.text())
  File "/home/ubuntu/.local/lib/python3.10/site-packages/aiogram/bot/api.py", line 128, in check_result
    raise exceptions.TelegramAPIError(description)
aiogram.utils.exceptions.TelegramAPIError: Bad Gateway
ERROR:aiogram.dispatcher.dispatcher:Cause exception while getting updates.
Traceback (most recent call last):
  File "/home/ubuntu/.local/lib/python3.10/site-packages/aiogram/dispatcher/dispatcher.py", line 381, in start_polling
    updates = await self.bot.get_updates(
  File "/home/ubuntu/.local/lib/python3.10/site-packages/aiogram/bot/bot.py", line 110, in get_updates
    result = await self.request(api.Methods.GET_UPDATES, payload)
  File "/home/ubuntu/.local/lib/python3.10/site-packages/aiogram/bot/base.py", line 236, in request
    return await api.make_request(await self.get_session(), self.server, self.__token, method, data, files,
  File "/home/ubuntu/.local/lib/python3.10/site-packages/aiogram/bot/api.py", line 140, in make_request
    return check_result(method, response.content_type, response.status, await response.text())
  File "/home/ubuntu/.local/lib/python3.10/site-packages/aiogram/bot/api.py", line 128, in check_result
    raise exceptions.TelegramAPIError(description)
aiogram.utils.exceptions.TelegramAPIError: Bad Gateway
ERROR:aiogram.dispatcher.dispatcher:Cause exception while getting updates.
Traceback (most recent call last):
  File "/home/ubuntu/.local/lib/python3.10/site-packages/aiogram/dispatcher/dispatcher.py", line 381, in start_polling
    updates = await self.bot.get_updates(
  File "/home/ubuntu/.local/lib/python3.10/site-packages/aiogram/bot/bot.py", line 110, in get_updates
    result = await self.request(api.Methods.GET_UPDATES, payload)
  File "/home/ubuntu/.local/lib/python3.10/site-packages/aiogram/bot/base.py", line 236, in request
    return await api.make_request(await self.get_session(), self.server, self.__token, method, data, files,
  File "/home/ubuntu/.local/lib/python3.10/site-packages/aiogram/bot/api.py", line 140, in make_request
    return check_result(method, response.content_type, response.status, await response.text())
  File "/home/ubuntu/.local/lib/python3.10/site-packages/aiogram/bot/api.py", line 111, in check_result
    raise exceptions.RetryAfter(parameters.retry_after)
aiogram.utils.exceptions.RetryAfter: Flood control exceeded. Retry in 5 seconds.
ERROR:aiogram.dispatcher.dispatcher:Cause exception while getting updates.
Traceback (most recent call last):
  File "/home/ubuntu/.local/lib/python3.10/site-packages/aiogram/dispatcher/dispatcher.py", line 381, in start_polling
    updates = await self.bot.get_updates(
  File "/home/ubuntu/.local/lib/python3.10/site-packages/aiogram/bot/bot.py", line 110, in get_updates
    result = await self.request(api.Methods.GET_UPDATES, payload)
  File "/home/ubuntu/.local/lib/python3.10/site-packages/aiogram/bot/base.py", line 236, in request
    return await api.make_request(await self.get_session(), self.server, self.__token, method, data, files,
  File "/home/ubuntu/.local/lib/python3.10/site-packages/aiogram/bot/api.py", line 140, in make_request
    return check_result(method, response.content_type, response.status, await response.text())
  File "/home/ubuntu/.local/lib/python3.10/site-packages/aiogram/bot/api.py", line 128, in check_result
    raise exceptions.TelegramAPIError(description)
aiogram.utils.exceptions.TelegramAPIError: Bad Gateway
ERROR:aiogram.dispatcher.dispatcher:Cause exception while getting updates.
Traceback (most recent call last):
  File "/home/ubuntu/.local/lib/python3.10/site-packages/aiogram/bot/api.py", line 139, in make_request
    async with session.post(url, data=req, **kwargs) as response:
  File "/home/ubuntu/.local/lib/python3.10/site-packages/aiohttp/client.py", line 1167, in __aenter__
    self._resp = await self._coro
  File "/home/ubuntu/.local/lib/python3.10/site-packages/aiohttp/client.py", line 586, in _request
    await resp.start(conn)
  File "/home/ubuntu/.local/lib/python3.10/site-packages/aiohttp/client_reqrep.py", line 905, in start
    message, payload = await protocol.read()  # type: ignore[union-attr]
  File "/home/ubuntu/.local/lib/python3.10/site-packages/aiohttp/streams.py", line 616, in read
    await self._waiter
aiohttp.client_exceptions.ClientOSError: [Errno 104] Connection reset by peer

During handling of the above exception, another exception occurred:

Traceback (most recent call last):
  File "/home/ubuntu/.local/lib/python3.10/site-packages/aiogram/dispatcher/dispatcher.py", line 381, in start_polling
    updates = await self.bot.get_updates(
  File "/home/ubuntu/.local/lib/python3.10/site-packages/aiogram/bot/bot.py", line 110, in get_updates
    result = await self.request(api.Methods.GET_UPDATES, payload)
  File "/home/ubuntu/.local/lib/python3.10/site-packages/aiogram/bot/base.py", line 236, in request
    return await api.make_request(await self.get_session(), self.server, self.__token, method, data, files,
  File "/home/ubuntu/.local/lib/python3.10/site-packages/aiogram/bot/api.py", line 142, in make_request
    raise exceptions.NetworkError(f"aiohttp client throws an error: {e.__class__.__name__}: {e}")
aiogram.utils.exceptions.NetworkError: Aiohttp client throws an error: ClientOSError: [Errno 104] Connection reset by peer
ERROR:aiogram.dispatcher.dispatcher:Cause exception while getting updates.
Traceback (most recent call last):
  File "/home/ubuntu/.local/lib/python3.10/site-packages/aiogram/dispatcher/dispatcher.py", line 381, in start_polling
    updates = await self.bot.get_updates(
  File "/home/ubuntu/.local/lib/python3.10/site-packages/aiogram/bot/bot.py", line 110, in get_updates
    result = await self.request(api.Methods.GET_UPDATES, payload)
  File "/home/ubuntu/.local/lib/python3.10/site-packages/aiogram/bot/base.py", line 236, in request
    return await api.make_request(await self.get_session(), self.server, self.__token, method, data, files,
  File "/home/ubuntu/.local/lib/python3.10/site-packages/aiogram/bot/api.py", line 140, in make_request
    return check_result(method, response.content_type, response.status, await response.text())
  File "/home/ubuntu/.local/lib/python3.10/site-packages/aiogram/bot/api.py", line 111, in check_result
    raise exceptions.RetryAfter(parameters.retry_after)
aiogram.utils.exceptions.RetryAfter: Flood control exceeded. Retry in 5 seconds.
ERROR:aiogram.dispatcher.dispatcher:Cause exception while getting updates.
Traceback (most recent call last):
  File "/home/ubuntu/.local/lib/python3.10/site-packages/aiogram/dispatcher/dispatcher.py", line 381, in start_polling
    updates = await self.bot.get_updates(
  File "/home/ubuntu/.local/lib/python3.10/site-packages/aiogram/bot/bot.py", line 110, in get_updates
    result = await self.request(api.Methods.GET_UPDATES, payload)
  File "/home/ubuntu/.local/lib/python3.10/site-packages/aiogram/bot/base.py", line 236, in request
    return await api.make_request(await self.get_session(), self.server, self.__token, method, data, files,
  File "/home/ubuntu/.local/lib/python3.10/site-packages/aiogram/bot/api.py", line 140, in make_request
    return check_result(method, response.content_type, response.status, await response.text())
  File "/home/ubuntu/.local/lib/python3.10/site-packages/aiogram/bot/api.py", line 128, in check_result
    raise exceptions.TelegramAPIError(description)
aiogram.utils.exceptions.TelegramAPIError: Bad Gateway
ERROR:aiogram.dispatcher.dispatcher:Cause exception while getting updates.
Traceback (most recent call last):
  File "/home/ubuntu/.local/lib/python3.10/site-packages/aiogram/dispatcher/dispatcher.py", line 381, in start_polling
    updates = await self.bot.get_updates(
  File "/home/ubuntu/.local/lib/python3.10/site-packages/aiogram/bot/bot.py", line 110, in get_updates
    result = await self.request(api.Methods.GET_UPDATES, payload)
  File "/home/ubuntu/.local/lib/python3.10/site-packages/aiogram/bot/base.py", line 236, in request
    return await api.make_request(await self.get_session(), self.server, self.__token, method, data, files,
  File "/home/ubuntu/.local/lib/python3.10/site-packages/aiogram/bot/api.py", line 140, in make_request
    return check_result(method, response.content_type, response.status, await response.text())
  File "/home/ubuntu/.local/lib/python3.10/site-packages/aiogram/bot/api.py", line 128, in check_result
    raise exceptions.TelegramAPIError(description)
aiogram.utils.exceptions.TelegramAPIError: Bad Gateway
ERROR:aiogram.dispatcher.dispatcher:Cause exception while getting updates.
Traceback (most recent call last):
  File "/home/ubuntu/.local/lib/python3.10/site-packages/aiogram/dispatcher/dispatcher.py", line 381, in start_polling
    updates = await self.bot.get_updates(
  File "/home/ubuntu/.local/lib/python3.10/site-packages/aiogram/bot/bot.py", line 110, in get_updates
    result = await self.request(api.Methods.GET_UPDATES, payload)
  File "/home/ubuntu/.local/lib/python3.10/site-packages/aiogram/bot/base.py", line 236, in request
    return await api.make_request(await self.get_session(), self.server, self.__token, method, data, files,
  File "/home/ubuntu/.local/lib/python3.10/site-packages/aiogram/bot/api.py", line 140, in make_request
    return check_result(method, response.content_type, response.status, await response.text())
  File "/home/ubuntu/.local/lib/python3.10/site-packages/aiogram/bot/api.py", line 128, in check_result
    raise exceptions.TelegramAPIError(description)
aiogram.utils.exceptions.TelegramAPIError: Bad Gateway
ERROR:aiogram.dispatcher.dispatcher:Cause exception while getting updates.
Traceback (most recent call last):
  File "/home/ubuntu/.local/lib/python3.10/site-packages/aiogram/bot/api.py", line 139, in make_request
    async with session.post(url, data=req, **kwargs) as response:
  File "/home/ubuntu/.local/lib/python3.10/site-packages/aiohttp/client.py", line 1167, in __aenter__
    self._resp = await self._coro
  File "/home/ubuntu/.local/lib/python3.10/site-packages/aiohttp/client.py", line 586, in _request
    await resp.start(conn)
  File "/home/ubuntu/.local/lib/python3.10/site-packages/aiohttp/client_reqrep.py", line 905, in start
    message, payload = await protocol.read()  # type: ignore[union-attr]
  File "/home/ubuntu/.local/lib/python3.10/site-packages/aiohttp/streams.py", line 616, in read
    await self._waiter
aiohttp.client_exceptions.ClientOSError: [Errno 104] Connection reset by peer

During handling of the above exception, another exception occurred:

Traceback (most recent call last):
  File "/home/ubuntu/.local/lib/python3.10/site-packages/aiogram/dispatcher/dispatcher.py", line 381, in start_polling
    updates = await self.bot.get_updates(
  File "/home/ubuntu/.local/lib/python3.10/site-packages/aiogram/bot/bot.py", line 110, in get_updates
    result = await self.request(api.Methods.GET_UPDATES, payload)
  File "/home/ubuntu/.local/lib/python3.10/site-packages/aiogram/bot/base.py", line 236, in request
    return await api.make_request(await self.get_session(), self.server, self.__token, method, data, files,
  File "/home/ubuntu/.local/lib/python3.10/site-packages/aiogram/bot/api.py", line 142, in make_request
    raise exceptions.NetworkError(f"aiohttp client throws an error: {e.__class__.__name__}: {e}")
aiogram.utils.exceptions.NetworkError: Aiohttp client throws an error: ClientOSError: [Errno 104] Connection reset by peer
ERROR:aiogram.dispatcher.dispatcher:Cause exception while getting updates.
Traceback (most recent call last):
  File "/home/ubuntu/.local/lib/python3.10/site-packages/aiogram/dispatcher/dispatcher.py", line 381, in start_polling
    updates = await self.bot.get_updates(
  File "/home/ubuntu/.local/lib/python3.10/site-packages/aiogram/bot/bot.py", line 110, in get_updates
    result = await self.request(api.Methods.GET_UPDATES, payload)
  File "/home/ubuntu/.local/lib/python3.10/site-packages/aiogram/bot/base.py", line 236, in request
    return await api.make_request(await self.get_session(), self.server, self.__token, method, data, files,
  File "/home/ubuntu/.local/lib/python3.10/site-packages/aiogram/bot/api.py", line 140, in make_request
    return check_result(method, response.content_type, response.status, await response.text())
  File "/home/ubuntu/.local/lib/python3.10/site-packages/aiogram/bot/api.py", line 111, in check_result
    raise exceptions.RetryAfter(parameters.retry_after)
aiogram.utils.exceptions.RetryAfter: Flood control exceeded. Retry in 5 seconds.
ERROR:aiogram.dispatcher.dispatcher:Cause exception while getting updates.
Traceback (most recent call last):
  File "/home/ubuntu/.local/lib/python3.10/site-packages/aiogram/dispatcher/dispatcher.py", line 381, in start_polling
    updates = await self.bot.get_updates(
  File "/home/ubuntu/.local/lib/python3.10/site-packages/aiogram/bot/bot.py", line 110, in get_updates
    result = await self.request(api.Methods.GET_UPDATES, payload)
  File "/home/ubuntu/.local/lib/python3.10/site-packages/aiogram/bot/base.py", line 236, in request
    return await api.make_request(await self.get_session(), self.server, self.__token, method, data, files,
  File "/home/ubuntu/.local/lib/python3.10/site-packages/aiogram/bot/api.py", line 140, in make_request
    return check_result(method, response.content_type, response.status, await response.text())
  File "/home/ubuntu/.local/lib/python3.10/site-packages/aiogram/bot/api.py", line 128, in check_result
    raise exceptions.TelegramAPIError(description)
aiogram.utils.exceptions.TelegramAPIError: Bad Gateway
ERROR:aiogram.dispatcher.dispatcher:Cause exception while getting updates.
Traceback (most recent call last):
  File "/home/ubuntu/.local/lib/python3.10/site-packages/aiogram/dispatcher/dispatcher.py", line 381, in start_polling
    updates = await self.bot.get_updates(
  File "/home/ubuntu/.local/lib/python3.10/site-packages/aiogram/bot/bot.py", line 110, in get_updates
    result = await self.request(api.Methods.GET_UPDATES, payload)
  File "/home/ubuntu/.local/lib/python3.10/site-packages/aiogram/bot/base.py", line 236, in request
    return await api.make_request(await self.get_session(), self.server, self.__token, method, data, files,
  File "/home/ubuntu/.local/lib/python3.10/site-packages/aiogram/bot/api.py", line 140, in make_request
    return check_result(method, response.content_type, response.status, await response.text())
  File "/home/ubuntu/.local/lib/python3.10/site-packages/aiogram/bot/api.py", line 128, in check_result
    raise exceptions.TelegramAPIError(description)
aiogram.utils.exceptions.TelegramAPIError: Bad Gateway
ERROR:aiogram.dispatcher.dispatcher:Cause exception while getting updates.
Traceback (most recent call last):
  File "/home/ubuntu/.local/lib/python3.10/site-packages/aiogram/dispatcher/dispatcher.py", line 381, in start_polling
    updates = await self.bot.get_updates(
  File "/home/ubuntu/.local/lib/python3.10/site-packages/aiogram/bot/bot.py", line 110, in get_updates
    result = await self.request(api.Methods.GET_UPDATES, payload)
  File "/home/ubuntu/.local/lib/python3.10/site-packages/aiogram/bot/base.py", line 236, in request
    return await api.make_request(await self.get_session(), self.server, self.__token, method, data, files,
  File "/home/ubuntu/.local/lib/python3.10/site-packages/aiogram/bot/api.py", line 140, in make_request
    return check_result(method, response.content_type, response.status, await response.text())
  File "/home/ubuntu/.local/lib/python3.10/site-packages/aiogram/bot/api.py", line 128, in check_result
    raise exceptions.TelegramAPIError(description)
aiogram.utils.exceptions.TelegramAPIError: Bad Gateway
ERROR:aiogram.dispatcher.dispatcher:Cause exception while getting updates.
Traceback (most recent call last):
  File "/home/ubuntu/.local/lib/python3.10/site-packages/aiogram/dispatcher/dispatcher.py", line 381, in start_polling
    updates = await self.bot.get_updates(
  File "/home/ubuntu/.local/lib/python3.10/site-packages/aiogram/bot/bot.py", line 110, in get_updates
    result = await self.request(api.Methods.GET_UPDATES, payload)
  File "/home/ubuntu/.local/lib/python3.10/site-packages/aiogram/bot/base.py", line 236, in request
    return await api.make_request(await self.get_session(), self.server, self.__token, method, data, files,
  File "/home/ubuntu/.local/lib/python3.10/site-packages/aiogram/bot/api.py", line 140, in make_request
    return check_result(method, response.content_type, response.status, await response.text())
  File "/home/ubuntu/.local/lib/python3.10/site-packages/aiogram/bot/api.py", line 111, in check_result
    raise exceptions.RetryAfter(parameters.retry_after)
aiogram.utils.exceptions.RetryAfter: Flood control exceeded. Retry in 5 seconds.
ERROR:aiogram.dispatcher.dispatcher:Cause exception while getting updates.
Traceback (most recent call last):
  File "/home/ubuntu/.local/lib/python3.10/site-packages/aiogram/dispatcher/dispatcher.py", line 381, in start_polling
    updates = await self.bot.get_updates(
  File "/home/ubuntu/.local/lib/python3.10/site-packages/aiogram/bot/bot.py", line 110, in get_updates
    result = await self.request(api.Methods.GET_UPDATES, payload)
  File "/home/ubuntu/.local/lib/python3.10/site-packages/aiogram/bot/base.py", line 236, in request
    return await api.make_request(await self.get_session(), self.server, self.__token, method, data, files,
  File "/home/ubuntu/.local/lib/python3.10/site-packages/aiogram/bot/api.py", line 140, in make_request
    return check_result(method, response.content_type, response.status, await response.text())
  File "/home/ubuntu/.local/lib/python3.10/site-packages/aiogram/bot/api.py", line 128, in check_result
    raise exceptions.TelegramAPIError(description)
aiogram.utils.exceptions.TelegramAPIError: Bad Gateway
ERROR:aiogram.dispatcher.dispatcher:Cause exception while getting updates.
Traceback (most recent call last):
  File "/home/ubuntu/.local/lib/python3.10/site-packages/aiogram/bot/api.py", line 139, in make_request
    async with session.post(url, data=req, **kwargs) as response:
  File "/home/ubuntu/.local/lib/python3.10/site-packages/aiohttp/client.py", line 1167, in __aenter__
    self._resp = await self._coro
  File "/home/ubuntu/.local/lib/python3.10/site-packages/aiohttp/client.py", line 586, in _request
    await resp.start(conn)
  File "/home/ubuntu/.local/lib/python3.10/site-packages/aiohttp/client_reqrep.py", line 905, in start
    message, payload = await protocol.read()  # type: ignore[union-attr]
  File "/home/ubuntu/.local/lib/python3.10/site-packages/aiohttp/streams.py", line 616, in read
    await self._waiter
aiohttp.client_exceptions.ClientOSError: [Errno 104] Connection reset by peer

During handling of the above exception, another exception occurred:

Traceback (most recent call last):
  File "/home/ubuntu/.local/lib/python3.10/site-packages/aiogram/dispatcher/dispatcher.py", line 381, in start_polling
    updates = await self.bot.get_updates(
  File "/home/ubuntu/.local/lib/python3.10/site-packages/aiogram/bot/bot.py", line 110, in get_updates
    result = await self.request(api.Methods.GET_UPDATES, payload)
  File "/home/ubuntu/.local/lib/python3.10/site-packages/aiogram/bot/base.py", line 236, in request
    return await api.make_request(await self.get_session(), self.server, self.__token, method, data, files,
  File "/home/ubuntu/.local/lib/python3.10/site-packages/aiogram/bot/api.py", line 142, in make_request
    raise exceptions.NetworkError(f"aiohttp client throws an error: {e.__class__.__name__}: {e}")
aiogram.utils.exceptions.NetworkError: Aiohttp client throws an error: ClientOSError: [Errno 104] Connection reset by peer
